/**
 * Registering a unhandledRejection handler that throws the provided exception ensures that code
 * that has an unhandled rejection fails a test case and does not let failing code continue unnoticed.
 * This is the warning this code replaces: UnhandledPromiseRejectionWarning: Unhandled promise
 * rejection. This error originated either by throwing inside of an async function without a catch block,
 * or by rejecting a promise which was not handled with .catch(). (rejection id: 1)
 */
export declare function crashOnUnhandledRejections(): void;
